Workbook

Sheet Vlookup
K17: Źródło: | L17: https://www.kaggle.com/yasserh/song-popularity-dataset?select=song_data.csv
A18: Funkcje VLOOKUP i MATCH | K18: Dane do zadań z karty | AA18: Zadanie 1
A19: Funkcja VLOOKUP (WYSZUKAJ.PIONOWO) to kręgosłup Excela. Wraz z MATCH (PODAJ.POZYCJĘ) tworzą potęzną parę. | K19: song_name | L19: song_popularity | M19: song_duration_ms | N19: acousticness | O19: danceability | P19: energy | Q19: instrumentalness | R19: key | S19: liveness | T19: loudness | U19: audio_mode | V19: speechiness | W19: tempo | X19: time_signature | Y19: audio_valence | AA19: Użyj funkcji VLOOKUP, aby wyszukać wartości z kolumw nagłówkach
K20: Boulevard of Broken Dreams | L20: 73 | M20: 262333 | N20: 0.00552 | O20: 0.496 | P20: 0.682 | Q20: 2.94e-05 | R20: 8 | S20: 0.0589 | T20: -4.095 | U20: 1 | V20: 0.0294 | W20: 167.06 | X20: 4 | Y20: 0.474
K21: In The End | L21: 66 | M21: 216933 | N21: 0.0103 | O21: 0.542 | P21: 0.853 | Q21: 0 | R21: 3 | S21: 0.108 | T21: -6.407 | U21: 0 | V21: 0.0498 | W21: 105.256 | X21: 4 | Y21: 0.37
A22: VLOOKUP: | K22: Seven Nation Army | L22: 76 | M22: 231733 | N22: 0.00817 | O22: 0.737 | P22: 0.463 | Q22: 0.447 | R22: 0 | S22: 0.255 | T22: -7.828 | U22: 1 | V22: 0.0792 | W22: 123.881 | X22: 4 | Y22: 0.324 | AA22: Nr kolumny:
K23: By The Way | L23: 74 | M23: 216933 | N23: 0.0264 | O23: 0.451 | P23: 0.97 | Q23: 0.00355 | R23: 0 | S23: 0.102 | T23: -4.938 | U23: 1 | V23: 0.107 | W23: 122.444 | X23: 4 | Y23: 0.198 | AA23: Piosenka | AB23: song_popularity | AC23: danceability | AD23: tempo
B24: =VLOOKUP(WARTOŚĆ, ZAKRES,Nr. Kolumny, TYP.DOPASOWANIA) | K24: How You Remind Me | L24: 56 | M24: 223826 | N24: 0.000954 | O24: 0.447 | P24: 0.766 | Q24: 0 | R24: 10 | S24: 0.113 | T24: -5.065 | U24: 1 | V24: 0.0313 | W24: 172.011 | X24: 4 | Y24: 0.574 | AA24: Chop Suey!
K25: Bring Me To Life | L25: 80 | M25: 235893 | N25: 0.00895 | O25: 0.316 | P25: 0.945 | Q25: 1.85e-06 | R25: 4 | S25: 0.396 | T25: -3.169 | U25: 0 | V25: 0.124 | W25: 189.931 | X25: 4 | Y25: 0.32 | AA25: What's My Age Again?
A26: Gdzie: | K26: Last Resort | L26: 81 | M26: 199893 | N26: 0.000504 | O26: 0.581 | P26: 0.887 | Q26: 0.00111 | R26: 4 | S26: 0.268 | T26: -3.659 | U26: 0 | V26: 0.0624 | W26: 90.578 | X26: 4 | Y26: 0.724 | AA26: Numb
K27: Are You Gonna Be My Girl | L27: 76 | M27: 213800 | N27: 0.00148 | O27: 0.613 | P27: 0.953 | Q27: 0.000582 | R27: 2 | S27: 0.152 | T27: -3.435 | U27: 1 | V27: 0.0855 | W27: 105.046 | X27: 4 | Y27: 0.537
B28: WARTOŚĆ | C28: - | D28: Poszukiwana przez nas wartość w 1 kolumnie tablicy | K28: Mr. Brightside | L28: 80 | M28: 222586 | N28: 0.00108 | O28: 0.33 | P28: 0.936 | Q28: 0 | R28: 1 | S28: 0.0926 | T28: -3.66 | U28: 1 | V28: 0.0917 | W28: 148.112 | X28: 4 | Y28: 0.234
K29: Sex on Fire | L29: 81 | M29: 203346 | N29: 0.00172 | O29: 0.542 | P29: 0.905 | Q29: 0.0104 | R29: 9 | S29: 0.136 | T29: -5.653 | U29: 1 | V29: 0.054 | W29: 153.398 | X29: 4 | Y29: 0.374 | AA29: Zadanie 2
B30: ZAKRES | C30: - | D30: Wybrana przez nas tablica | K30: The Middle | L30: 78 | M30: 168253 | N30: 0.0424 | O30: 0.629 | P30: 0.897 | Q30: 0 | R30: 2 | S30: 0.263 | T30: -3.401 | U30: 1 | V30: 0.0483 | W30: 161.944 | X30: 4 | Y30: 0.93 | AA30: Użyf unkcji MATCH (PODAJ.POZYCJE), aby znaleźć w której kolumnie są następujące dane:
K31: Numb | L31: 63 | M31: 185586 | N31: 0.0046 | O31: 0.496 | P31: 0.863 | Q31: 0 | R31: 9 | S31: 0.639 | T31: -4.153 | U31: 1 | V31: 0.0381 | W31: 110.018 | X31: 4 | Y31: 0.243
B32: Nr. Kolumny | C32: - | D32: Kolumna w naszej wybranej tablicy, którą mamy zwrócić | K32: Smooth Criminal | L32: 75 | M32: 209266 | N32: 0.00434 | O32: 0.647 | P32: 0.964 | Q32: 0.0036 | R32: 9 | S32: 0.15 | T32: -4.225 | U32: 0 | V32: 0.06 | W32: 126.942 | X32: 4 | Y32: 0.875
K33: Can't Stop | L33: 81 | M33: 269000 | N33: 0.0179 | O33: 0.618 | P33: 0.938 | Q33: 0 | R33: 9 | S33: 0.167 | T33: -3.442 | U33: 1 | V33: 0.0456 | W33: 91.455 | X33: 4 | Y33: 0.875 | AA33: Zmienna | AB33: audio_mode | AC33: energy | AD33: instrumentalness
B34: TYP.DOPASOWANIA | C34: - | D34: FAŁSZ dopasowuje dokładnie wybrany tekst PRAWDA - najbliższy pasujący (może dać dziwny wynik przy liczbach) | K34: Chop Suey! | L34: 69 | M34: 210240 | N34: 0.000353 | O34: 0.42 | P34: 0.929 | Q34: 0.000747 | R34: 7 | S34: 0.122 | T34: -3.899 | U34: 0 | V34: 0.121 | W34: 127.204 | X34: 4 | Y34: 0.3 | AA34: Nr Kolumny
K35: Take Me Out | L35: 77 | M35: 237026 | N35: 0.000423 | O35: 0.278 | P35: 0.676 | Q35: 0.000899 | R35: 9 | S35: 0.136 | T35: -8.821 | U35: 1 | V35: 0.0371 | W35: 104.545 | X35: 4 | Y35: 0.494
A36: MATCH: | K36: I Miss You | L36: 71 | M36: 227240 | N36: 0.00136 | O36: 0.659 | P36: 0.778 | Q36: 6.79e-06 | R36: 11 | S36: 0.0841 | T36: -6.423 | U36: 1 | V36: 0.0379 | W36: 110.022 | X36: 4 | Y36: 0.623
K37: Best of You | L37: 62 | M37: 256600 | N37: 0.00701 | O37: 0.37 | P37: 0.944 | Q37: 2.9e-06 | R37: 1 | S37: 0.135 | T37: -4.979 | U37: 0 | V37: 0.0767 | W37: 130.315 | X37: 4 | Y37: 0.345
B38: =MATCH(WARTOŚĆ, ZAKRES, TYP.DOPASOWANIA) | K38: I Write Sins Not Tragedies | L38: 77 | M38: 187613 | N38: 0.0938 | O38: 0.567 | P38: 0.795 | Q38: 0 | R38: 9 | S38: 0.114 | T38: -4.985 | U38: 0 | V38: 0.134 | W38: 170.06 | X38: 4 | Y38: 0.635 | AA38: Zadanie 3
K39: Kryptonite | L39: 79 | M39: 233933 | N39: 0.00664 | O39: 0.545 | P39: 0.865 | Q39: 1.12e-05 | R39: 11 | S39: 0.168 | T39: -5.708 | U39: 0 | V39: 0.0286 | W39: 99.01 | X39: 4 | Y39: 0.543 | AA39: Połączmy umiejętności z zadań 1 i 2, aby rozwiązać tabelę bez wpisywania numerów kolumn
B40: WARTOŚĆ | C40: - | D40: Poszukiwana przez nas wartość w 1 kolumnie tablic | K40: The Kill (Bury Me) | L40: 69 | M40: 231533 | N40: 0.0014 | O40: 0.309 | P40: 0.912 | Q40: 0.000271 | R40: 4 | S40: 0.582 | T40: -3.881 | U40: 0 | V40: 0.0646 | W40: 183.035 | X40: 3 | Y40: 0.302
K41: Use Somebody | L41: 79 | M41: 230760 | N41: 0.00552 | O41: 0.276 | P41: 0.715 | Q41: 0.000417 | R41: 0 | S41: 0.201 | T41: -5.356 | U41: 1 | V41: 0.0432 | W41: 137.028 | X41: 4 | Y41: 0.173
B42: ZAKRES | C42: - | D42: Wybrana przez nas tablica | K42: No One Knows | L42: 13 | M42: 255066 | N42: 0.0137 | O42: 0.518 | P42: 0.538 | Q42: 0.000398 | R42: 0 | S42: 0.141 | T42: -5.818 | U42: 1 | V42: 0.0486 | W42: 170.953 | X42: 4 | Y42: 0.687
K43: Jerk It Out | L43: 62 | M43: 195666 | N43: 0.0171 | O43: 0.58 | P43: 0.981 | Q43: 1.07e-05 | R43: 8 | S43: 0.386 | T43: -2.603 | U43: 0 | V43: 0.06 | W43: 134.007 | X43: 4 | Y43: 0.861 | AA43: Piosenka | AB43: song_popularity | AC43: danceability | AD43: tempo
B44: TYP.DOPASOWANIA | C44: - | D44: 1 - największa wartość poniżej szukanej wartości (wymaga posortowania) 0 - dokładne wybieranie szukanej wartości -1 - najmniejsza wartość powyżej szukanej wartości (wymaga posortowania) | K44: Uprising | L44: 77 | M44: 304840 | N44: 0.000202 | O44: 0.602 | P44: 0.905 | Q44: 0.064 | R44: 2 | S44: 0.117 | T44: -4.046 | U44: 1 | V44: 0.0775 | W44: 128.019 | X44: 4 | Y44: 0.411 | AA44: Chop Suey!
K45: Hey There Delilah | L45: 79 | M45: 232533 | N45: 0.872 | O45: 0.657 | P45: 0.291 | Q45: 0 | R45: 2 | S45: 0.114 | T45: -10.572 | U45: 1 | V45: 0.0293 | W45: 103.973 | X45: 4 | Y45: 0.298 | AA45: What's My Age Again?
K46: Blurry | L46: 28 | M46: 303920 | N46: 0.0102 | O46: 0.44 | P46: 0.932 | Q46: 0 | R46: 3 | S46: 0.142 | T46: -4.488 | U46: 0 | V46: 0.0584 | W46: 157.438 | X46: 4 | Y46: 0.495 | AA46: Numb
K47: American Idiot | L47: 78 | M47: 176346 | N47: 2.64e-05 | O47: 0.38 | P47: 0.988 | Q47: 7.86e-05 | R47: 1 | S47: 0.368 | T47: -2.042 | U47: 1 | V47: 0.0639 | W47: 186.113 | X47: 4 | Y47: 0.769
A48: Wykonamy 3 zadania, które pokażą nam jej funkcjonalność | K48: Welcome to the Black Parade | L48: 77 | M48: 311106 | N48: 0.000289 | O48: 0.217 | P48: 0.905 | Q48: 0.00011 | R48: 2 | S48: 0.222 | T48: -4.103 | U48: 1 | V48: 0.0752 | W48: 96.95 | X48: 4 | Y48: 0.236
K49: Gives You Hell | L49: 71 | M49: 213106 | N49: 0.0156 | O49: 0.714 | P49: 0.725 | Q49: 0 | R49: 4 | S49: 0.0726 | T49: -6.411 | U49: 1 | V49: 0.0402 | W49: 99.988 | X49: 4 | Y49: 0.59
K50: All My Life | L50: 11 | M50: 262733 | N50: 0.000194 | O50: 0.582 | P50: 0.597 | Q50: 0.000273 | R50: 5 | S50: 0.517 | T50: -5.671 | U50: 1 | V50: 0.0512 | W50: 167.738 | X50: 4 | Y50: 0.674
K51: Like a Stone | L51: 77 | M51: 293960 | N51: 0.00797 | O51: 0.614 | P51: 0.568 | Q51: 0 | R51: 7 | S51: 0.0997 | T51: -5.477 | U51: 0 | V51: 0.0276 | W51: 107.849 | X51: 4 | Y51: 0.516
K52: It's Been Awhile | L52: 65 | M52: 264706 | N52: 0.00189 | O52: 0.509 | P52: 0.774 | Q52: 0.000549 | R52: 6 | S52: 0.143 | T52: -4.054 | U52: 1 | V52: 0.0338 | W52: 116.529 | X52: 4 | Y52: 0.0824
K53: I Hate Everything About You | L53: 75 | M53: 231480 | N53: 0.00461 | O53: 0.498 | P53: 0.83 | Q53: 0 | R53: 6 | S53: 0.139 | T53: -5.157 | U53: 0 | V53: 0.0421 | W53: 89.342 | X53: 4 | Y53: 0.453
K54: Rollin' (Air Raid Vehicle) | L54: 74 | M54: 213760 | N54: 0.00506 | O54: 0.599 | P54: 0.932 | Q54: 0 | R54: 9 | S54: 0.269 | T54: -3.328 | U54: 1 | V54: 0.18 | W54: 96.234 | X54: 4 | Y54: 0.692
K55: Fat Lip | L55: 74 | M55: 178266 | N55: 0.000618 | O55: 0.574 | P55: 0.911 | Q55: 0 | R55: 9 | S55: 0.0769 | T55: -5.176 | U55: 1 | V55: 0.0715 | W55: 98.075 | X55: 4 | Y55: 0.573
K56: The Pretender | L56: 11 | M56: 269373 | N56: 0.000917 | O56: 0.433 | P56: 0.959 | Q56: 0 | R56: 9 | S56: 0.028 | T56: -4.04 | U56: 1 | V56: 0.0431 | W56: 172.984 | X56: 4 | Y56: 0.365
...

Sheet Vlookup2
B4: Zadanie - Uzupełnij tabelę wydaktów militarnych na podstawie
B6: https://www.sipri.org/databases
B15: Wydatki % PKB | F15: Wydatki % budżetu
D16: 2020 | H16: 2020
B17: Russia | C17: Rosja | F17: Russia | G17: Rosja
B18: USA | C18: USA | F18: USA | G18: USA
B19: Germany | C19: Niemcy | F19: Germany | G19: Niemcy
B20: Poland | C20: Polska | F20: Poland | G20: Polska
B21: Ukraine | C21: Ukraina | F21: Ukraine | G21: Ukraina
B22: France | C22: Francja | F22: France | G22: Francja
B23: Italy | C23: Włochy | F23: Italy | G23: Włochy
B24: China | C24: Chiny | F24: China | G24: Chiny
B25: Sweden | C25: Szwecja | F25: Sweden | G25: Szwecja
B26: Finland | C26: Finlandia | F26: Finland | G26: Finlandia

Sheet Indeks
I17: Źródło: | K17: https://stat.gov.pl/wskazniki-makroekonomiczne/ | AM17: Źródło: | AN17: https://www.kaggle.com/jmcslk/ballon-d-or-data-analysis/data
A18: Funkcja Indeks | I18: Dane do zadań - zwróćcie uwagę jaka formuła je wyciągnęła z tabeli | U18: Zadanie 1 - Dynamiczne wykresy | AC18: Zadanie 2 - Vlookup na lewo | AK18: Dane - zadanie 2
A19: Indeks to chyba najbardziej niedoceniana funkcja Excela. | I19: Nr wiersza z tabeli | M19: 19 | N19: 24 | O19: 25 | P19: 26 | Q19: 27 | R19: 28 | U19: Funkcji INDEKS może pomóc za jednym ruchem dużo zmieniać na wykresie. | AC19: Ograniczeniem funkcji Vlookup (WYSZUKAJ.PIONOWO) jest wybór danych z pierwszej kolumny z lewej strony. Funkcja INDEKS nie uznaje takich ograniczeń. Połączymy ja z Match (PODAJ.POZYCJĘ), aby znaleźć informacje po lewej stronie. Pytanie: W którym roku CR7 i Leo Messi byli po raz pierwszy nominowanie do złotej piłki. Na którym miejscu skończyli rywalizacje? | AL19: year | AM19: rank | AN19: player | AO19: team | AP19: points | AQ19: percentages
I20: Nr kolumny z tabeli | J20: LP | K20: Okres | M20: Przeciętne wynagrodzenie - przemysł | N20: Przeciętne wynagrodzenie - budownictwo | O20: Przeciętne wynagrodzenie - handel | P20: Przeciętne wynagrodzenie - transport | Q20: Przeciętne wynagrodzenie - informacja i komunikacja | R20: Przeciętne wynagrodzenie - finanse | AK20: 0 | AL20: 1956 | AM20: 1st | AN20: Stanley Matthews | AO20: Blackpool | AP20: 47 | AQ20: 37.9
A21: Zwraca wybrany element tablicy. Działa następująco: | I21: =COLUMN(Dane_Index!BL5) -> 64 | J21: 1 | K21: 2015 | L21: I | M21: =IF(ISNUMBER(INDEX(Dane_Index!$1:$1048576,M$19,$I21)),INDEX(Dane_Index!$1:$1048576,M$19,$I21),NA()) -> 4111.89 | N21: =IF(ISNUMBER(INDEX(Dane_Index!$1:$1048576,N$19,$I21)),INDEX(Dane_Index!$1:$1048576,N$19,$I21),NA()) -> 3899.01 | O21: =IF(ISNUMBER(INDEX(Dane_Index!$1:$1048576,O$19,$I21)),INDEX(Dane_Index!$1:$1048576,O$19,$I21),NA()) -> 3723.97 | P21: =IF(ISNUMBER(INDEX(Dane_Index!$1:$1048576,P$19,$I21)),INDEX(Dane_Index!$1:$1048576,P$19,$I21),NA()) -> 3656.08 | Q21: =IF(ISNUMBER(INDEX(Dane_Index!$1:$1048576,Q$19,$I21)),INDEX(Dane_Index!$1:$1048576,Q$19,$I21),NA()) -> 7299.99 | R21: =IF(ISNUMBER(INDEX(Dane_Index!$1:$1048576,R$19,$I21)),INDEX(Dane_Index!$1:$1048576,R$19,$I21),NA()) -> 7240.12 | AK21: 1 | AL21: 1956 | AM21: 2nd | AN21: Alfredo Di StÃ©fano | AO21: Real Madrid | AP21: 44 | AQ21: 35.48
I22: =I21+1 -> 65 | J22: 2 | L22: II | M22: =IF(ISNUMBER(INDEX(Dane_Index!$1:$1048576,M$19,$I22)),INDEX(Dane_Index!$1:$1048576,M$19,$I22),NA()) -> 4120.43 | N22: =IF(ISNUMBER(INDEX(Dane_Index!$1:$1048576,N$19,$I22)),INDEX(Dane_Index!$1:$1048576,N$19,$I22),NA()) -> 4042.29 | O22: =IF(ISNUMBER(INDEX(Dane_Index!$1:$1048576,O$19,$I22)),INDEX(Dane_Index!$1:$1048576,O$19,$I22),NA()) -> 3703.1 | P22: =IF(ISNUMBER(INDEX(Dane_Index!$1:$1048576,P$19,$I22)),INDEX(Dane_Index!$1:$1048576,P$19,$I22),NA()) -> 3757.29 | Q22: =IF(ISNUMBER(INDEX(Dane_Index!$1:$1048576,Q$19,$I22)),INDEX(Dane_Index!$1:$1048576,Q$19,$I22),NA()) -> 7280.78 | R22: =IF(ISNUMBER(INDEX(Dane_Index!$1:$1048576,R$19,$I22)),INDEX(Dane_Index!$1:$1048576,R$19,$I22),NA()) -> 6906 | X22: 1 | Y22: 3 | AK22: 2 | AL22: 1956 | AM22: 3rd | AN22: Raymond Kopa | AO22: Real Madrid | AP22: 33 | AQ22: 26.61
B23: =INDEX(ZAKRES,Nr. Wiersza, Nr. Kolumny) | I23: =I22+1 -> 66 | J23: 3 | L23: III | M23: =IF(ISNUMBER(INDEX(Dane_Index!$1:$1048576,M$19,$I23)),INDEX(Dane_Index!$1:$1048576,M$19,$I23),NA()) -> 4124.24 | N23: =IF(ISNUMBER(INDEX(Dane_Index!$1:$1048576,N$19,$I23)),INDEX(Dane_Index!$1:$1048576,N$19,$I23),NA()) -> 4111.21 | O23: =IF(ISNUMBER(INDEX(Dane_Index!$1:$1048576,O$19,$I23)),INDEX(Dane_Index!$1:$1048576,O$19,$I23),NA()) -> 3677.22 | P23: =IF(ISNUMBER(INDEX(Dane_Index!$1:$1048576,P$19,$I23)),INDEX(Dane_Index!$1:$1048576,P$19,$I23),NA()) -> 3831.3 | Q23: =IF(ISNUMBER(INDEX(Dane_Index!$1:$1048576,Q$19,$I23)),INDEX(Dane_Index!$1:$1048576,Q$19,$I23),NA()) -> 7142.81 | R23: =IF(ISNUMBER(INDEX(Dane_Index!$1:$1048576,R$19,$I23)),INDEX(Dane_Index!$1:$1048576,R$19,$I23),NA()) -> 6583.08 | V23: Okres | X23: =PROPER(SUBSTITUTE(INDEX($M$20:$R$20,X$22),"Przeciętne wynagrodzenie - ","")) -> Przemysł | Y23: =PROPER(SUBSTITUTE(INDEX($M$20:$R$20,Y$22),"Przeciętne wynagrodzenie - ","")) -> Handel | Z23: ="Relacja " &X23&"/"&Y23 -> Relacja Przemysł/Handel | AA23: ="Relacja " &X23&"/"&Y23 &" - średnia 3m" -> Relacja Przemysł/Handel - średnia 3m | AK23: 3 | AL23: 1957 | AM23: 1st | AN23: Alfredo Di StÃ©fano | AO23: Real Madrid | AP23: 72 | AQ23: 58.54
I24: =I23+1 -> 67 | J24: 4 | L24: IV | M24: =IF(ISNUMBER(INDEX(Dane_Index!$1:$1048576,M$19,$I24)),INDEX(Dane_Index!$1:$1048576,M$19,$I24),NA()) -> 4406.61 | N24: =IF(ISNUMBER(INDEX(Dane_Index!$1:$1048576,N$19,$I24)),INDEX(Dane_Index!$1:$1048576,N$19,$I24),NA()) -> 4249.78 | O24: =IF(ISNUMBER(INDEX(Dane_Index!$1:$1048576,O$19,$I24)),INDEX(Dane_Index!$1:$1048576,O$19,$I24),NA()) -> 3702.12 | P24: =IF(ISNUMBER(INDEX(Dane_Index!$1:$1048576,P$19,$I24)),INDEX(Dane_Index!$1:$1048576,P$19,$I24),NA()) -> 4089.43 | Q24: =IF(ISNUMBER(INDEX(Dane_Index!$1:$1048576,Q$19,$I24)),INDEX(Dane_Index!$1:$1048576,Q$19,$I24),NA()) -> 7171.27 | R24: =IF(ISNUMBER(INDEX(Dane_Index!$1:$1048576,R$19,$I24)),INDEX(Dane_Index!$1:$1048576,R$19,$I24),NA()) -> 6820.58 | U24: 1 | V24: 2015 | W24: I | Z24: =IF(ISNUMBER(X24),X24/Y24,NA()) -> #N/A | AA24: =NA() -> #N/A | AK24: 4 | AL24: 1957 | AM24: 2nd | AN24: Billy Wright | AO24: Wolverhampton Wanderers | AP24: 19 | AQ24: 15.45
A25: Gdzie: | I25: =I24+1 -> 68 | J25: 5 | K25: =K21+1 -> 2016 | L25: I | M25: =IF(ISNUMBER(INDEX(Dane_Index!$1:$1048576,M$19,$I25)),INDEX(Dane_Index!$1:$1048576,M$19,$I25),NA()) -> 4233.42 | N25: =IF(ISNUMBER(INDEX(Dane_Index!$1:$1048576,N$19,$I25)),INDEX(Dane_Index!$1:$1048576,N$19,$I25),NA()) -> 4042.8 | O25: =IF(ISNUMBER(INDEX(Dane_Index!$1:$1048576,O$19,$I25)),INDEX(Dane_Index!$1:$1048576,O$19,$I25),NA()) -> 3887.89 | P25: =IF(ISNUMBER(INDEX(Dane_Index!$1:$1048576,P$19,$I25)),INDEX(Dane_Index!$1:$1048576,P$19,$I25),NA()) -> 3767.09 | Q25: =IF(ISNUMBER(INDEX(Dane_Index!$1:$1048576,Q$19,$I25)),INDEX(Dane_Index!$1:$1048576,Q$19,$I25),NA()) -> 7599.24 | R25: =IF(ISNUMBER(INDEX(Dane_Index!$1:$1048576,R$19,$I25)),INDEX(Dane_Index!$1:$1048576,R$19,$I25),NA()) -> 7329.59 | U25: 2 | W25: II | Z25: =IF(ISNUMBER(X25),X25/Y25,NA()) -> #N/A | AA25: =NA() -> #N/A | AD25: Rok | AE25: Miejsce | AF25: Klub | AK25: 5 | AL25: 1957 | AM25: 3rd | AN25: Duncan Edwards | AO25: Manchester United | AP25: 16 | AQ25: 13.01
B26: ZAKRES | C26: - | D26: Wybrana przez nas tablica | I26: =I25+1 -> 69 | J26: 6 | L26: II | M26: =IF(ISNUMBER(INDEX(Dane_Index!$1:$1048576,M$19,$I26)),INDEX(Dane_Index!$1:$1048576,M$19,$I26),NA()) -> 4252.65 | N26: =IF(ISNUMBER(INDEX(Dane_Index!$1:$1048576,N$19,$I26)),INDEX(Dane_Index!$1:$1048576,N$19,$I26),NA()) -> 4296.46 | O26: =IF(ISNUMBER(INDEX(Dane_Index!$1:$1048576,O$19,$I26)),INDEX(Dane_Index!$1:$1048576,O$19,$I26),NA()) -> 3934.17 | P26: =IF(ISNUMBER(INDEX(Dane_Index!$1:$1048576,P$19,$I26)),INDEX(Dane_Index!$1:$1048576,P$19,$I26),NA()) -> 3884.53 | Q26: =IF(ISNUMBER(INDEX(Dane_Index!$1:$1048576,Q$19,$I26)),INDEX(Dane_Index!$1:$1048576,Q$19,$I26),NA()) -> 7593.05 | R26: =IF(ISNUMBER(INDEX(Dane_Index!$1:$1048576,R$19,$I26)),INDEX(Dane_Index!$1:$1048576,R$19,$I26),NA()) -> 7017.37 | U26: 3 | W26: III | Z26: =IF(ISNUMBER(X26),X26/Y26,NA()) -> #N/A | AA26: =AVERAGE(Z24:Z26) -> #N/A | AC26: Cristiano Ronaldo | AK26: 6 | AL26: 1957 | AM26: 3rd | AN26: Raymond Kopa | AO26: Real Madrid | AP26: 16 | AQ26: 13.01
I27: =I26+1 -> 70 | J27: 7 | L27: III | M27: =IF(ISNUMBER(INDEX(Dane_Index!$1:$1048576,M$19,$I27)),INDEX(Dane_Index!$1:$1048576,M$19,$I27),NA()) -> 4315.08 | N27: =IF(ISNUMBER(INDEX(Dane_Index!$1:$1048576,N$19,$I27)),INDEX(Dane_Index!$1:$1048576,N$19,$I27),NA()) -> 4257.77 | O27: =IF(ISNUMBER(INDEX(Dane_Index!$1:$1048576,O$19,$I27)),INDEX(Dane_Index!$1:$1048576,O$19,$I27),NA()) -> 3902 | P27: =IF(ISNUMBER(INDEX(Dane_Index!$1:$1048576,P$19,$I27)),INDEX(Dane_Index!$1:$1048576,P$19,$I27),NA()) -> 3966.77 | Q27: =IF(ISNUMBER(INDEX(Dane_Index!$1:$1048576,Q$19,$I27)),INDEX(Dane_Index!$1:$1048576,Q$19,$I27),NA()) -> 7316.85 | R27: =IF(ISNUMBER(INDEX(Dane_Index!$1:$1048576,R$19,$I27)),INDEX(Dane_Index!$1:$1048576,R$19,$I27),NA()) -> 6936.01 | U27: 4 | W27: IV | Z27: =IF(ISNUMBER(X27),X27/Y27,NA()) -> #N/A | AA27: =AVERAGE(Z25:Z27) -> #N/A | AC27: Lionel Messi | AK27: 7 | AL27: 1958 | AM27: 1st | AN27: Raymond Kopa | AO27: Real Madrid | AP27: 71 | AQ27: 52.99
B28: Nr. Wiersza | C28: - | D28: Wiersz w naszej wybranej tablicy | I28: =I27+1 -> 71 | J28: 8 | L28: IV | M28: =IF(ISNUMBER(INDEX(Dane_Index!$1:$1048576,M$19,$I28)),INDEX(Dane_Index!$1:$1048576,M$19,$I28),NA()) -> 4498.18 | N28: =IF(ISNUMBER(INDEX(Dane_Index!$1:$1048576,N$19,$I28)),INDEX(Dane_Index!$1:$1048576,N$19,$I28),NA()) -> 4408.35 | O28: =IF(ISNUMBER(INDEX(Dane_Index!$1:$1048576,O$19,$I28)),INDEX(Dane_Index!$1:$1048576,O$19,$I28),NA()) -> 3871.17 | P28: =IF(ISNUMBER(INDEX(Dane_Index!$1:$1048576,P$19,$I28)),INDEX(Dane_Index!$1:$1048576,P$19,$I28),NA()) -> 4225.82 | Q28: =IF(ISNUMBER(INDEX(Dane_Index!$1:$1048576,Q$19,$I28)),INDEX(Dane_Index!$1:$1048576,Q$19,$I28),NA()) -> 7762.5 | R28: =IF(ISNUMBER(INDEX(Dane_Index!$1:$1048576,R$19,$I28)),INDEX(Dane_Index!$1:$1048576,R$19,$I28),NA()) -> 6965.46 | U28: 5 | V28: =V24+1 -> 2016 | W28: I | Z28: =IF(ISNUMBER(X28),X28/Y28,NA()) -> #N/A | AA28: =AVERAGE(Z26:Z28) -> #N/A | AK28: 8 | AL28: 1958 | AM28: 2nd | AN28: Helmut Rahn | AO28: Rot-Weiss Essen | AP28: 40 | AQ28: 29.85
I29: =I28+1 -> 72 | J29: 9 | K29: =K25+1 -> 2017 | L29: I | M29: =IF(ISNUMBER(INDEX(Dane_Index!$1:$1048576,M$19,$I29)),INDEX(Dane_Index!$1:$1048576,M$19,$I29),NA()) -> 4408.47 | N29: =IF(ISNUMBER(INDEX(Dane_Index!$1:$1048576,N$19,$I29)),INDEX(Dane_Index!$1:$1048576,N$19,$I29),NA()) -> 4267.02 | O29: =IF(ISNUMBER(INDEX(Dane_Index!$1:$1048576,O$19,$I29)),INDEX(Dane_Index!$1:$1048576,O$19,$I29),NA()) -> 4148.02 | P29: =IF(ISNUMBER(INDEX(Dane_Index!$1:$1048576,P$19,$I29)),INDEX(Dane_Index!$1:$1048576,P$19,$I29),NA()) -> 3906.89 | Q29: =IF(ISNUMBER(INDEX(Dane_Index!$1:$1048576,Q$19,$I29)),INDEX(Dane_Index!$1:$1048576,Q$19,$I29),NA()) -> 7879.1 | R29: =IF(ISNUMBER(INDEX(Dane_Index!$1:$1048576,R$19,$I29)),INDEX(Dane_Index!$1:$1048576,R$19,$I29),NA()) -> 7680.19 | U29: 6 | W29: II | Z29: =IF(ISNUMBER(X29),X29/Y29,NA()) -> #N/A | AA29: =AVERAGE(Z27:Z29) -> #N/A | AK29: 9 | AL29: 1958 | AM29: 3rd | AN29: Just Fontaine | AO29: Stade de Reims | AP29: 23 | AQ29: 17.16
B30: Nr. Kolumny | C30: - | D30: Kolumna w naszej wybranej tablicy | I30: =I29+1 -> 73 | J30: 10 | L30: II | M30: =IF(ISNUMBER(INDEX(Dane_Index!$1:$1048576,M$19,$I30)),INDEX(Dane_Index!$1:$1048576,M$19,$I30),NA()) -> 4504.89 | N30: =IF(ISNUMBER(INDEX(Dane_Index!$1:$1048576,N$19,$I30)),INDEX(Dane_Index!$1:$1048576,N$19,$I30),NA()) -> 4466.95 | O30: =IF(ISNUMBER(INDEX(Dane_Index!$1:$1048576,O$19,$I30)),INDEX(Dane_Index!$1:$1048576,O$19,$I30),NA()) -> 4201.81 | P30: =IF(ISNUMBER(INDEX(Dane_Index!$1:$1048576,P$19,$I30)),INDEX(Dane_Index!$1:$1048576,P$19,$I30),NA()) -> 4054.33 | Q30: =IF(ISNUMBER(INDEX(Dane_Index!$1:$1048576,Q$19,$I30)),INDEX(Dane_Index!$1:$1048576,Q$19,$I30),NA()) -> 7864.12 | R30: =IF(ISNUMBER(INDEX(Dane_Index!$1:$1048576,R$19,$I30)),INDEX(Dane_Index!$1:$1048576,R$19,$I30),NA()) -> 7617.38 | U30: 7 | W30: III | Z30: =IF(ISNUMBER(X30),X30/Y30,NA()) -> #N/A | AA30: =AVERAGE(Z28:Z30) -> #N/A | AK30: 10 | AL30: 1959 | AM30: 1st | AN30: Alfredo Di StÃ©fano | AO30: Real Madrid | AP30: 80 | AQ30: 54.79
I31: =I30+1 -> 74 | J31: 11 | L31: III | M31: =IF(ISNUMBER(INDEX(Dane_Index!$1:$1048576,M$19,$I31)),INDEX(Dane_Index!$1:$1048576,M$19,$I31),NA()) -> 4540.04 | N31: =IF(ISNUMBER(INDEX(Dane_Index!$1:$1048576,N$19,$I31)),INDEX(Dane_Index!$1:$1048576,N$19,$I31),NA()) -> 4572.97 | O31: =IF(ISNUMBER(INDEX(Dane_Index!$1:$1048576,O$19,$I31)),INDEX(Dane_Index!$1:$1048576,O$19,$I31),NA()) -> 4181.35 | P31: =IF(ISNUMBER(INDEX(Dane_Index!$1:$1048576,P$19,$I31)),INDEX(Dane_Index!$1:$1048576,P$19,$I31),NA()) -> 4168.34 | Q31: =IF(ISNUMBER(INDEX(Dane_Index!$1:$1048576,Q$19,$I31)),INDEX(Dane_Index!$1:$1048576,Q$19,$I31),NA()) -> 7825.5 | R31: =IF(ISNUMBER(INDEX(Dane_Index!$1:$1048576,R$19,$I31)),INDEX(Dane_Index!$1:$1048576,R$19,$I31),NA()) -> 7158.32 | U31: 8 | W31: IV | Z31: =IF(ISNUMBER(X31),X31/Y31,NA()) -> #N/A | AA31: =AVERAGE(Z29:Z31) -> #N/A | AK31: 11 | AL31: 1959 | AM31: 2nd | AN31: Raymond Kopa | AO31: Real Madrid | AP31: 42 | AQ31: 28.77
I32: =I31+1 -> 75 | J32: 12 | L32: IV | M32: =IF(ISNUMBER(INDEX(Dane_Index!$1:$1048576,M$19,$I32)),INDEX(Dane_Index!$1:$1048576,M$19,$I32),NA()) -> 4805.63 | N32: =IF(ISNUMBER(INDEX(Dane_Index!$1:$1048576,N$19,$I32)),INDEX(Dane_Index!$1:$1048576,N$19,$I32),NA()) -> 4816.68 | O32: =IF(ISNUMBER(INDEX(Dane_Index!$1:$1048576,O$19,$I32)),INDEX(Dane_Index!$1:$1048576,O$19,$I32),NA()) -> 4291.26 | P32: =IF(ISNUMBER(INDEX(Dane_Index!$1:$1048576,P$19,$I32)),INDEX(Dane_Index!$1:$1048576,P$19,$I32),NA()) -> 4523.08 | Q32: =IF(ISNUMBER(INDEX(Dane_Index!$1:$1048576,Q$19,$I32)),INDEX(Dane_Index!$1:$1048576,Q$19,$I32),NA()) -> 7948.16 | R32: =IF(ISNUMBER(INDEX(Dane_Index!$1:$1048576,R$19,$I32)),INDEX(Dane_Index!$1:$1048576,R$19,$I32),NA()) -> 7354.18 | U32: 9 | V32: =V28+1 -> 2017 | W32: I | Z32: =IF(ISNUMBER(X32),X32/Y32,NA()) -> #N/A | AA32: =AVERAGE(Z30:Z32) -> #N/A | AK32: 12 | AL32: 1959 | AM32: 3rd | AN32: John Charles | AO32: Juventus | AP32: 24 | AQ32: 16.44
A33: Wykonamy 3 zadania, które pokażą nam jej funkcjonalność | I33: =I32+1 -> 76 | J33: 13 | K33: =K29+1 -> 2018 | L33: I | M33: =IF(ISNUMBER(INDEX(Dane_Index!$1:$1048576,M$19,$I33)),INDEX(Dane_Index!$1:$1048576,M$19,$I33),NA()) -> 4705.67 | N33: =IF(ISNUMBER(INDEX(Dane_Index!$1:$1048576,N$19,$I33)),INDEX(Dane_Index!$1:$1048576,N$19,$I33),NA()) -> 4592.89 | O33: =IF(ISNUMBER(INDEX(Dane_Index!$1:$1048576,O$19,$I33)),INDEX(Dane_Index!$1:$1048576,O$19,$I33),NA()) -> 4443.41 | P33: =IF(ISNUMBER(INDEX(Dane_Index!$1:$1048576,P$19,$I33)),INDEX(Dane_Index!$1:$1048576,P$19,$I33),NA()) -> 4167.51 | Q33: =IF(ISNUMBER(INDEX(Dane_Index!$1:$1048576,Q$19,$I33)),INDEX(Dane_Index!$1:$1048576,Q$19,$I33),NA()) -> 8500.58 | R33: =IF(ISNUMBER(INDEX(Dane_Index!$1:$1048576,R$19,$I33)),INDEX(Dane_Index!$1:$1048576,R$19,$I33),NA()) -> 8190.82 | U33: 10 | W33: II | Z33: =IF(ISNUMBER(X33),X33/Y33,NA()) -> #N/A | AA33: =AVERAGE(Z31:Z33) -> #N/A | AK33: 13 | AL33: 1960 | AM33: 1st | AN33: Luis SuÃ¡rez | AO33: Barcelona | AP33: 54 | AQ33: 43.55
I34: =I33+1 -> 77 | J34: 14 | L34: II | M34: =IF(ISNUMBER(INDEX(Dane_Index!$1:$1048576,M$19,$I34)),INDEX(Dane_Index!$1:$1048576,M$19,$I34),NA()) -> 4857.38 | N34: =IF(ISNUMBER(INDEX(Dane_Index!$1:$1048576,N$19,$I34)),INDEX(Dane_Index!$1:$1048576,N$19,$I34),NA()) -> 4869.6 | O34: =IF(ISNUMBER(INDEX(Dane_Index!$1:$1048576,O$19,$I34)),INDEX(Dane_Index!$1:$1048576,O$19,$I34),NA()) -> 4516.23 | P34: =IF(ISNUMBER(INDEX(Dane_Index!$1:$1048576,P$19,$I34)),INDEX(Dane_Index!$1:$1048576,P$19,$I34),NA()) -> 4285.75 | Q34: =IF(ISNUMBER(INDEX(Dane_Index!$1:$1048576,Q$19,$I34)),INDEX(Dane_Index!$1:$1048576,Q$19,$I34),NA()) -> 8458.7 | R34: =IF(ISNUMBER(INDEX(Dane_Index!$1:$1048576,R$19,$I34)),INDEX(Dane_Index!$1:$1048576,R$19,$I34),NA()) -> 8006.79 | U34: 11 | W34: III | Z34: =IF(ISNUMBER(X34),X34/Y34,NA()) -> #N/A | AA34: =AVERAGE(Z32:Z34) -> #N/A | AK34: 14 | AL34: 1960 | AM34: 2nd | AN34: Ferenc PuskÃ¡s | AO34: Real Madrid | AP34: 37 | AQ34: 29.84
I35: =I34+1 -> 78 | J35: 15 | L35: III | M35: =IF(ISNUMBER(INDEX(Dane_Index!$1:$1048576,M$19,$I35)),INDEX(Dane_Index!$1:$1048576,M$19,$I35),NA()) -> 4854.78 | N35: =IF(ISNUMBER(INDEX(Dane_Index!$1:$1048576,N$19,$I35)),INDEX(Dane_Index!$1:$1048576,N$19,$I35),NA()) -> 5010.96 | O35: =IF(ISNUMBER(INDEX(Dane_Index!$1:$1048576,O$19,$I35)),INDEX(Dane_Index!$1:$1048576,O$19,$I35),NA()) -> 4485.01 | P35: =IF(ISNUMBER(INDEX(Dane_Index!$1:$1048576,P$19,$I35)),INDEX(Dane_Index!$1:$1048576,P$19,$I35),NA()) -> 4382.28 | Q35: =IF(ISNUMBER(INDEX(Dane_Index!$1:$1048576,Q$19,$I35)),INDEX(Dane_Index!$1:$1048576,Q$19,$I35),NA()) -> 8276.44 | R35: =IF(ISNUMBER(INDEX(Dane_Index!$1:$1048576,R$19,$I35)),INDEX(Dane_Index!$1:$1048576,R$19,$I35),NA()) -> 7562.98 | U35: 12 | W35: IV | Z35: =IF(ISNUMBER(X35),X35/Y35,NA()) -> #N/A | AA35: =AVERAGE(Z33:Z35) -> #N/A | AK35: 15 | AL35: 1960 | AM35: 3rd | AN35: Uwe Seeler | AO35: Hamburg | AP35: 33 | AQ35: 26.61
I36: =I35+1 -> 79 | J36: 16 | L36: IV | M36: =IF(ISNUMBER(INDEX(Dane_Index!$1:$1048576,M$19,$I36)),INDEX(Dane_Index!$1:$1048576,M$19,$I36),NA()) -> 5180.9 | N36: =IF(ISNUMBER(INDEX(Dane_Index!$1:$1048576,N$19,$I36)),INDEX(Dane_Index!$1:$1048576,N$19,$I36),NA()) -> 5119.68 | O36: =IF(ISNUMBER(INDEX(Dane_Index!$1:$1048576,O$19,$I36)),INDEX(Dane_Index!$1:$1048576,O$19,$I36),NA()) -> 4603.43 | P36: =IF(ISNUMBER(INDEX(Dane_Index!$1:$1048576,P$19,$I36)),INDEX(Dane_Index!$1:$1048576,P$19,$I36),NA()) -> 4723.04 | Q36: =IF(ISNUMBER(INDEX(Dane_Index!$1:$1048576,Q$19,$I36)),INDEX(Dane_Index!$1:$1048576,Q$19,$I36),NA()) -> 8477.04 | R36: =IF(ISNUMBER(INDEX(Dane_Index!$1:$1048576,R$19,$I36)),INDEX(Dane_Index!$1:$1048576,R$19,$I36),NA()) -> 7767.1 | U36: 13 | V36: =V32+1 -> 2018 | W36: I | Z36: =IF(ISNUMBER(X36),X36/Y36,NA()) -> #N/A | AA36: =AVERAGE(Z34:Z36) -> #N/A | AK36: 16 | AL36: 1961 | AM36: 1st | AN36: Omar SÃ­vori | AO36: Juventus | AP36: 46 | AQ36: 42.59
I37: =I36+1 -> 80 | J37: 17 | K37: =K33+1 -> 2019 | L37: I | M37: =IF(ISNUMBER(INDEX(Dane_Index!$1:$1048576,M$19,$I37)),INDEX(Dane_Index!$1:$1048576,M$19,$I37),NA()) -> 5035.98 | N37: =IF(ISNUMBER(INDEX(Dane_Index!$1:$1048576,N$19,$I37)),INDEX(Dane_Index!$1:$1048576,N$19,$I37),NA()) -> 4873.42 | O37: =IF(ISNUMBER(INDEX(Dane_Index!$1:$1048576,O$19,$I37)),INDEX(Dane_Index!$1:$1048576,O$19,$I37),NA()) -> 4751.4 | P37: =IF(ISNUMBER(INDEX(Dane_Index!$1:$1048576,P$19,$I37)),INDEX(Dane_Index!$1:$1048576,P$19,$I37),NA()) -> 4400.32 | Q37: =IF(ISNUMBER(INDEX(Dane_Index!$1:$1048576,Q$19,$I37)),INDEX(Dane_Index!$1:$1048576,Q$19,$I37),NA()) -> 8896.65 | R37: =IF(ISNUMBER(INDEX(Dane_Index!$1:$1048576,R$19,$I37)),INDEX(Dane_Index!$1:$1048576,R$19,$I37),NA()) -> 8539.55 | U37: 14 | W37: II | Z37: =IF(ISNUMBER(X37),X37/Y37,NA()) -> #N/A | AA37: =AVERAGE(Z35:Z37) -> #N/A | AK37: 17 | AL37: 1961 | AM37: 2nd | AN37: Luis SuÃ¡rez | AO37: Internazionale | AP37: 40 | AQ37: 37.04
I38: =I37+1 -> 81 | J38: 18 | L38: II | M38: =IF(ISNUMBER(INDEX(Dane_Index!$1:$1048576,M$19,$I38)),INDEX(Dane_Index!$1:$1048576,M$19,$I38),NA()) -> 5164.94 | N38: =IF(ISNUMBER(INDEX(Dane_Index!$1:$1048576,N$19,$I38)),INDEX(Dane_Index!$1:$1048576,N$19,$I38),NA()) -> 5283.01 | O38: =IF(ISNUMBER(INDEX(Dane_Index!$1:$1048576,O$19,$I38)),INDEX(Dane_Index!$1:$1048576,O$19,$I38),NA()) -> 4844.88 | P38: =IF(ISNUMBER(INDEX(Dane_Index!$1:$1048576,P$19,$I38)),INDEX(Dane_Index!$1:$1048576,P$19,$I38),NA()) -> 4533.99 | Q38: =IF(ISNUMBER(INDEX(Dane_Index!$1:$1048576,Q$19,$I38)),INDEX(Dane_Index!$1:$1048576,Q$19,$I38),NA()) -> 8964.9 | R38: =IF(ISNUMBER(INDEX(Dane_Index!$1:$1048576,R$19,$I38)),INDEX(Dane_Index!$1:$1048576,R$19,$I38),NA()) -> 8150.59 | U38: 15 | W38: III | Z38: =IF(ISNUMBER(X38),X38/Y38,NA()) -> #N/A | AA38: =AVERAGE(Z36:Z38) -> #N/A | AK38: 18 | AL38: 1961 | AM38: 3rd | AN38: Johnny Haynes | AO38: Fulham | AP38: 22 | AQ38: 20.37
I39: =I38+1 -> 82 | J39: 19 | L39: III | M39: =IF(ISNUMBER(INDEX(Dane_Index!$1:$1048576,M$19,$I39)),INDEX(Dane_Index!$1:$1048576,M$19,$I39),NA()) -> 5207.63 | N39: =IF(ISNUMBER(INDEX(Dane_Index!$1:$1048576,N$19,$I39)),INDEX(Dane_Index!$1:$1048576,N$19,$I39),NA()) -> 5234.73 | O39: =IF(ISNUMBER(INDEX(Dane_Index!$1:$1048576,O$19,$I39)),INDEX(Dane_Index!$1:$1048576,O$19,$I39),NA()) -> 4797.29 | P39: =IF(ISNUMBER(INDEX(Dane_Index!$1:$1048576,P$19,$I39)),INDEX(Dane_Index!$1:$1048576,P$19,$I39),NA()) -> 4637.46 | Q39: =IF(ISNUMBER(INDEX(Dane_Index!$1:$1048576,Q$19,$I39)),INDEX(Dane_Index!$1:$1048576,Q$19,$I39),NA()) -> 8492.08 | R39: =IF(ISNUMBER(INDEX(Dane_Index!$1:$1048576,R$19,$I39)),INDEX(Dane_Index!$1:$1048576,R$19,$I39),NA()) -> 8095.63 | U39: 16 | W39: IV | Z39: =IF(ISNUMBER(X39),X39/Y39,NA()) -> #N/A | AA39: =AVERAGE(Z37:Z39) -> #N/A | AK39: 19 | AL39: 1962 | AM39: 1st | AN39: Josef Masopust | AO39: Dukla Prague | AP39: 65 | AQ39: 43.05
I40: =I39+1 -> 83 | J40: 20 | L40: IV | M40: =IF(ISNUMBER(INDEX(Dane_Index!$1:$1048576,M$19,$I40)),INDEX(Dane_Index!$1:$1048576,M$19,$I40),NA()) -> 5448.29 | N40: =IF(ISNUMBER(INDEX(Dane_Index!$1:$1048576,N$19,$I40)),INDEX(Dane_Index!$1:$1048576,N$19,$I40),NA()) -> 5462.46 | O40: =IF(ISNUMBER(INDEX(Dane_Index!$1:$1048576,O$19,$I40)),INDEX(Dane_Index!$1:$1048576,O$19,$I40),NA()) -> 4908.84 | P40: =IF(ISNUMBER(INDEX(Dane_Index!$1:$1048576,P$19,$I40)),INDEX(Dane_Index!$1:$1048576,P$19,$I40),NA()) -> 4984.21 | Q40: =IF(ISNUMBER(INDEX(Dane_Index!$1:$1048576,Q$19,$I40)),INDEX(Dane_Index!$1:$1048576,Q$19,$I40),NA()) -> 8811.58 | R40: =IF(ISNUMBER(INDEX(Dane_Index!$1:$1048576,R$19,$I40)),INDEX(Dane_Index!$1:$1048576,R$19,$I40),NA()) -> 8159.23 | U40: 17 | V40: =V36+1 -> 2019 | W40: I | Z40: =IF(ISNUMBER(X40),X40/Y40,NA()) -> #N/A | AA40: =AVERAGE(Z38:Z40) -> #N/A | AK40: 20 | AL40: 1962 | AM40: 2nd | AN40: EusÃ©bio | AO40: Benfica | AP40: 53 | AQ40: 35.1
I41: =I40+1 -> 84 | J41: 21 | K41: =K37+1 -> 2020 | L41: I | M41: =IF(ISNUMBER(INDEX(Dane_Index!$1:$1048576,M$19,$I41)),INDEX(Dane_Index!$1:$1048576,M$19,$I41),NA()) -> 5368.95 | N41: =IF(ISNUMBER(INDEX(Dane_Index!$1:$1048576,N$19,$I41)),INDEX(Dane_Index!$1:$1048576,N$19,$I41),NA()) -> 5180.03 | O41: =IF(ISNUMBER(INDEX(Dane_Index!$1:$1048576,O$19,$I41)),INDEX(Dane_Index!$1:$1048576,O$19,$I41),NA()) -> 5118.87 | P41: =IF(ISNUMBER(INDEX(Dane_Index!$1:$1048576,P$19,$I41)),INDEX(Dane_Index!$1:$1048576,P$19,$I41),NA()) -> 4668 | Q41: =IF(ISNUMBER(INDEX(Dane_Index!$1:$1048576,Q$19,$I41)),INDEX(Dane_Index!$1:$1048576,Q$19,$I41),NA()) -> 9457.34 | R41: =IF(ISNUMBER(INDEX(Dane_Index!$1:$1048576,R$19,$I41)),INDEX(Dane_Index!$1:$1048576,R$19,$I41),NA()) -> 9461.46 | U41: 18 | W41: II | Z41: =IF(ISNUMBER(X41),X41/Y41,NA()) -> #N/A | AA41: =AVERAGE(Z39:Z41) -> #N/A | AK41: 21 | AL41: 1962 | AM41: 3rd | AN41: Karl-Heinz Schnellinger | AO41: KÃ¶ln | AP41: 33 | AQ41: 21.85
I42: =I41+1 -> 85 | J42: 22 | L42: II | M42: =IF(ISNUMBER(INDEX(Dane_Index!$1:$1048576,M$19,$I42)),INDEX(Dane_Index!$1:$1048576,M$19,$I42),NA()) -> 5212.61 | N42: =IF(ISNUMBER(INDEX(Dane_Index!$1:$1048576,N$19,$I42)),INDEX(Dane_Index!$1:$1048576,N$19,$I42),NA()) -> 5325.21 | O42: =IF(ISNUMBER(INDEX(Dane_Index!$1:$1048576,O$19,$I42)),INDEX(Dane_Index!$1:$1048576,O$19,$I42),NA()) -> 5017.82 | P42: =IF(ISNUMBER(INDEX(Dane_Index!$1:$1048576,P$19,$I42)),INDEX(Dane_Index!$1:$1048576,P$19,$I42),NA()) -> 4560.35 | Q42: =IF(ISNUMBER(INDEX(Dane_Index!$1:$1048576,Q$19,$I42)),INDEX(Dane_Index!$1:$1048576,Q$19,$I42),NA()) -> 9073.65 | R42: =IF(ISNUMBER(INDEX(Dane_Index!$1:$1048576,R$19,$I42)),INDEX(Dane_Index!$1:$1048576,R$19,$I42),NA()) -> 8757.83 | U42: 19 | W42: III | Z42: =IF(ISNUMBER(X42),X42/Y42,NA()) -> #N/A | AA42: =AVERAGE(Z40:Z42) -> #N/A | AK42: 22 | AL42: 1963 | AM42: 1st | AN42: Lev Yashin | AO42: Dynamo Moscow | AP42: 73 | AQ42: 45.91
I43: =I42+1 -> 86 | J43: 23 | L43: III | M43: =IF(ISNUMBER(INDEX(Dane_Index!$1:$1048576,M$19,$I43)),INDEX(Dane_Index!$1:$1048576,M$19,$I43),NA()) -> 5397.57 | N43: =IF(ISNUMBER(INDEX(Dane_Index!$1:$1048576,N$19,$I43)),INDEX(Dane_Index!$1:$1048576,N$19,$I43),NA()) -> 5490.26 | O43: =IF(ISNUMBER(INDEX(Dane_Index!$1:$1048576,O$19,$I43)),INDEX(Dane_Index!$1:$1048576,O$19,$I43),NA()) -> 4976.77 | P43: =IF(ISNUMBER(INDEX(Dane_Index!$1:$1048576,P$19,$I43)),INDEX(Dane_Index!$1:$1048576,P$19,$I43),NA()) -> 4742.85 | Q43: =IF(ISNUMBER(INDEX(Dane_Index!$1:$1048576,Q$19,$I43)),INDEX(Dane_Index!$1:$1048576,Q$19,$I43),NA()) -> 9191.28 | R43: =IF(ISNUMBER(INDEX(Dane_Index!$1:$1048576,R$19,$I43)),INDEX(Dane_Index!$1:$1048576,R$19,$I43),NA()) -> 8060.39 | U43: 20 | W43: IV | Z43: =IF(ISNUMBER(X43),X43/Y43,NA()) -> #N/A | AA43: =AVERAGE(Z41:Z43) -> #N/A | AK43: 23 | AL43: 1963 | AM43: 2nd | AN43: Gianni Rivera | AO43: Milan | AP43: 53 | AQ43: 33.33
I44: =I43+1 -> 87 | J44: 24 | L44: IV | M44: =IF(ISNUMBER(INDEX(Dane_Index!$1:$1048576,M$19,$I44)),INDEX(Dane_Index!$1:$1048576,M$19,$I44),NA()) -> 5818.05 | N44: =IF(ISNUMBER(INDEX(Dane_Index!$1:$1048576,N$19,$I44)),INDEX(Dane_Index!$1:$1048576,N$19,$I44),NA()) -> 5610.77 | O44: =IF(ISNUMBER(INDEX(Dane_Index!$1:$1048576,O$19,$I44)),INDEX(Dane_Index!$1:$1048576,O$19,$I44),NA()) -> 5121.16 | P44: =IF(ISNUMBER(INDEX(Dane_Index!$1:$1048576,P$19,$I44)),INDEX(Dane_Index!$1:$1048576,P$19,$I44),NA()) -> 5044.2 | Q44: =IF(ISNUMBER(INDEX(Dane_Index!$1:$1048576,Q$19,$I44)),INDEX(Dane_Index!$1:$1048576,Q$19,$I44),NA()) -> 9279.29 | R44: =IF(ISNUMBER(INDEX(Dane_Index!$1:$1048576,R$19,$I44)),INDEX(Dane_Index!$1:$1048576,R$19,$I44),NA()) -> 8308.22 | U44: 21 | V44: =V40+1 -> 2020 | W44: I | Z44: =IF(ISNUMBER(X44),X44/Y44,NA()) -> #N/A | AA44: =AVERAGE(Z42:Z44) -> #N/A | AK44: 24 | AL44: 1963 | AM44: 3rd | AN44: Jimmy Greaves | AO44: Tottenham Hotspur | AP44: 33 | AQ44: 20.75
I45: =I44+1 -> 88 | J45: 25 | K45: =K41+1 -> 2021 | L45: I | M45: =IF(ISNUMBER(INDEX(Dane_Index!$1:$1048576,M$19,$I45)),INDEX(Dane_Index!$1:$1048576,M$19,$I45),NA()) -> 5696.99 | N45: =IF(ISNUMBER(INDEX(Dane_Index!$1:$1048576,N$19,$I45)),INDEX(Dane_Index!$1:$1048576,N$19,$I45),NA()) -> 5374.33 | O45: =IF(ISNUMBER(INDEX(Dane_Index!$1:$1048576,O$19,$I45)),INDEX(Dane_Index!$1:$1048576,O$19,$I45),NA()) -> 5409.71 | P45: =IF(ISNUMBER(INDEX(Dane_Index!$1:$1048576,P$19,$I45)),INDEX(Dane_Index!$1:$1048576,P$19,$I45),NA()) -> 4811.71 | Q45: =IF(ISNUMBER(INDEX(Dane_Index!$1:$1048576,Q$19,$I45)),INDEX(Dane_Index!$1:$1048576,Q$19,$I45),NA()) -> 10007.26 | R45: =IF(ISNUMBER(INDEX(Dane_Index!$1:$1048576,R$19,$I45)),INDEX(Dane_Index!$1:$1048576,R$19,$I45),NA()) -> 9555.71 | U45: 22 | W45: II | Z45: =IF(ISNUMBER(X45),X45/Y45,NA()) -> #N/A | AA45: =AVERAGE(Z43:Z45) -> #N/A | AK45: 25 | AL45: 1964 | AM45: 1st | AN45: Denis Law | AO45: Manchester United | AP45: 61 | AQ45: 42.96
I46: =I45+1 -> 89 | J46: 26 | L46: II | M46: =IF(ISNUMBER(INDEX(Dane_Index!$1:$1048576,M$19,$I46)),INDEX(Dane_Index!$1:$1048576,M$19,$I46),NA()) -> 5806.87 | N46: =IF(ISNUMBER(INDEX(Dane_Index!$1:$1048576,N$19,$I46)),INDEX(Dane_Index!$1:$1048576,N$19,$I46),NA()) -> 5770.24 | O46: =IF(ISNUMBER(INDEX(Dane_Index!$1:$1048576,O$19,$I46)),INDEX(Dane_Index!$1:$1048576,O$19,$I46),NA()) -> 5436.56 | P46: =IF(ISNUMBER(INDEX(Dane_Index!$1:$1048576,P$19,$I46)),INDEX(Dane_Index!$1:$1048576,P$19,$I46),NA()) -> 4930.98 | Q46: =IF(ISNUMBER(INDEX(Dane_Index!$1:$1048576,Q$19,$I46)),INDEX(Dane_Index!$1:$1048576,Q$19,$I46),NA()) -> 9968.64 | R46: =IF(ISNUMBER(INDEX(Dane_Index!$1:$1048576,R$19,$I46)),INDEX(Dane_Index!$1:$1048576,R$19,$I46),NA()) -> 8986.86 | U46: 23 | W46: III | Z46: =IF(ISNUMBER(X46),X46/Y46,NA()) -> #N/A | AA46: =AVERAGE(Z44:Z46) -> #N/A | AK46: 26 | AL46: 1964 | AM46: 2nd | AN46: Luis SuÃ¡rez | AO46: Internazionale | AP46: 43 | AQ46: 30.28
I47: =I46+1 -> 90 | J47: 27 | L47: III | M47: =IF(ISNUMBER(INDEX(Dane_Index!$1:$1048576,M$19,$I47)),INDEX(Dane_Index!$1:$1048576,M$19,$I47),NA()) -> 5881.63 | N47: =IF(ISNUMBER(INDEX(Dane_Index!$1:$1048576,N$19,$I47)),INDEX(Dane_Index!$1:$1048576,N$19,$I47),NA()) -> 5983.87 | O47: =IF(ISNUMBER(INDEX(Dane_Index!$1:$1048576,O$19,$I47)),INDEX(Dane_Index!$1:$1048576,O$19,$I47),NA()) -> 5513.59 | P47: =IF(ISNUMBER(INDEX(Dane_Index!$1:$1048576,P$19,$I47)),INDEX(Dane_Index!$1:$1048576,P$19,$I47),NA()) -> 5131.22 | Q47: =IF(ISNUMBER(INDEX(Dane_Index!$1:$1048576,Q$19,$I47)),INDEX(Dane_Index!$1:$1048576,Q$19,$I47),NA()) -> 9951.79 | R47: =IF(ISNUMBER(INDEX(Dane_Index!$1:$1048576,R$19,$I47)),INDEX(Dane_Index!$1:$1048576,R$19,$I47),NA()) -> 8959.93 | U47: 24 | W47: IV | Z47: =IF(ISNUMBER(X47),X47/Y47,NA()) -> #N/A | AA47: =AVERAGE(Z45:Z47) -> #N/A | AK47: 27 | AL47: 1964 | AM47: 3rd | AN47: Amancio | AO47: Real Madrid | AP47: 38 | AQ47: 26.76
I48: =I47+1 -> 91 | J48: 28 | L48: IV | M48: =IF(ISNUMBER(INDEX(Dane_Index!$1:$1048576,M$19,$I48)),INDEX(Dane_Index!$1:$1048576,M$19,$I48),NA()) -> #N/A | N48: =IF(ISNUMBER(INDEX(Dane_Index!$1:$1048576,N$19,$I48)),INDEX(Dane_Index!$1:$1048576,N$19,$I48),NA()) -> #N/A | O48: =IF(ISNUMBER(INDEX(Dane_Index!$1:$1048576,O$19,$I48)),INDEX(Dane_Index!$1:$1048576,O$19,$I48),NA()) -> #N/A | P48: =IF(ISNUMBER(INDEX(Dane_Index!$1:$1048576,P$19,$I48)),INDEX(Dane_Index!$1:$1048576,P$19,$I48),NA()) -> #N/A | Q48: =IF(ISNUMBER(INDEX(Dane_Index!$1:$1048576,Q$19,$I48)),INDEX(Dane_Index!$1:$1048576,Q$19,$I48),NA()) -> #N/A | R48: =IF(ISNUMBER(INDEX(Dane_Index!$1:$1048576,R$19,$I48)),INDEX(Dane_Index!$1:$1048576,R$19,$I48),NA()) -> #N/A | U48: 25 | V48: =V44+1 -> 2021 | W48: I | Z48: =IF(ISNUMBER(X48),X48/Y48,NA()) -> #N/A | AA48: =AVERAGE(Z46:Z48) -> #N/A | AK48: 28 | AL48: 1965 | AM48: 1st | AN48: EusÃ©bio | AO48: Benfica | AP48: 67 | AQ48: 39.18
U49: 26 | W49: II | Z49: =IF(ISNUMBER(X49),X49/Y49,NA()) -> #N/A | AA49: =AVERAGE(Z47:Z49) -> #N/A | AK49: 29 | AL49: 1965 | AM49: 2nd | AN49: Giacinto Facchetti | AO49: Internazionale | AP49: 59 | AQ49: 34.5
U50: 27 | W50: III | Z50: =IF(ISNUMBER(X50),X50/Y50,NA()) -> #N/A | AA50: =AVERAGE(Z48:Z50) -> #N/A | AK50: 30 | AL50: 1965 | AM50: 3rd | AN50: Luis SuÃ¡rez | AO50: Internazionale | AP50: 45 | AQ50: 26.32
U51: 28 | W51: IV | Z51: =IF(ISNUMBER(X51),X51/Y51,NA()) -> #N/A | AA51: =AVERAGE(Z49:Z51) -> #N/A | AK51: 31 | AL51: 1966 | AM51: 1st | AN51: Bobby Charlton | AO51: Manchester United | AP51: 81 | AQ51: 36.82
AK52: 32 | AL52: 1966 | AM52: 2nd | AN52: EusÃ©bio | AO52: Benfica | AP52: 80 | AQ52: 36.36
AK53: 33 | AL53: 1966 | AM53: 3rd | AN53: Franz Beckenbauer | AO53: Bayern Munich | AP53: 59 | AQ53: 26.82
AK54: 34 | AL54: 1967 | AM54: 1st | AN54: FlÃ³riÃ¡n Albert | AO54: FerencvÃ¡ros | AP54: 68 | AQ54: 46.26
AK55: 35 | AL55: 1967 | AM55: 2nd | AN55: Bobby Charlton | AO55: Manchester United | AP55: 40 | AQ55: 27.21
AK56: 36 | AL56: 1967 | AM56: 3rd | AN56: Jimmy Johnstone | AO56: Celtic | AP56: 39 | AQ56: 26.53
...

Sheet Offset
A18: Funkcja Przesunięcie | I18: Zadanie 1 - Biuletyn Statystyczny | Q18: Zadanie 2 - Biuletyn Statystyczny
A19: OFFSET to ciekawa funkcja w przypadku arkuszy GUS | I19: W sztandarowej publikacji GUS Biuletynie Statystycznym, ktoś wpadł na świetny pomysł, aby podawać dane co 2 kolumnę. Zbierzmy je do kupy wykorzystująć OFFSET (Przesunięcie) | Q19: Przekształćmy częstotliwość danych z miesięczną na roczną - użyjmy sumy
I21: Wartości pomocnicze | K21: 0 | L21: 1 | M21: 3 | N21: 26 | O21: 27
A22: Buduje odniesienie do komórki i zakresu znajdującego się w określonej pozycji | I22: LP | J22: Data | K22: =OFFSET(Dane_Offset!$B$5,0,2*K21) -> Ogółem Grand total | L22: =OFFSET(Dane_Offset!$B$5,0,2*L21) -> Górnictwo i wydobywanie Mining and quarrying | M22: =OFFSET(Dane_Offset!$B$5,0,2*M21) -> Przetwórstwo przemysłowe Manufacturing | N22: =OFFSET(Dane_Offset!$B$5,0,2*N21) -> Wytwarzanie i zaopatrywanie w energię elektryczną, gaz, parę wodną i gorącą wodę∆ Electricity, gas, steam and air conditioning supply | O22: =OFFSET(Dane_Offset!$B$5,0,2*O21) -> Dostawa wody; gospodarowanie ściekami i odpadami; rekultywacja∆ Water supply; sewerage, waste management and remediation activities | R22: =K22 -> Ogółem Grand total | S22: =L22 -> Górnictwo i wydobywanie Mining and quarrying | T22: =M22 -> Przetwórstwo przemysłowe Manufacturing | U22: =N22 -> Wytwarzanie i zaopatrywanie w energię elektryczną, gaz, parę wodną i gorącą wodę∆ Electricity, gas, steam and air conditioning supply | V22: =O22 -> Dostawa wody; gospodarowanie ściekami i odpadami; rekultywacja∆ Water supply; sewerage, waste management and remediation activities
B23: =OFFSET(ZAKRES,Nr. Wiersza, Nr. Kolumny) | I23: 1 | J23: 40179 | Q23: 2010
I24: =I23+1 -> 2 | J24: =EOMONTH(J23,0)+1 -> 40210 | Q24: =Q23+1 -> 2011
A25: Gdzie: | I25: =I24+1 -> 3 | J25: =EOMONTH(J24,0)+1 -> 40238 | Q25: =Q24+1 -> 2012
B26: ZAKRES | C26: - | D26: Wybrana przez nas komórka lub zakres | I26: =I25+1 -> 4 | J26: =EOMONTH(J25,0)+1 -> 40269 | Q26: =Q25+1 -> 2013
I27: =I26+1 -> 5 | J27: =EOMONTH(J26,0)+1 -> 40299 | Q27: =Q26+1 -> 2014
B28: Nr. Wiersza | C28: - | D28: O ile komórek w dół przesunąć zakres | I28: =I27+1 -> 6 | J28: =EOMONTH(J27,0)+1 -> 40330 | Q28: =Q27+1 -> 2015
I29: =I28+1 -> 7 | J29: =EOMONTH(J28,0)+1 -> 40360 | Q29: =Q28+1 -> 2016
B30: Nr. Kolumny | C30: - | D30: O ile komórek w prawo przesunąć zakres | I30: =I29+1 -> 8 | J30: =EOMONTH(J29,0)+1 -> 40391 | Q30: =Q29+1 -> 2017
I31: =I30+1 -> 9 | J31: =EOMONTH(J30,0)+1 -> 40422 | Q31: =Q30+1 -> 2018
I32: =I31+1 -> 10 | J32: =EOMONTH(J31,0)+1 -> 40452 | Q32: =Q31+1 -> 2019
A33: Wykonamy 2 zadania, które pokażą nam jej funkcjonalność | I33: =I32+1 -> 11 | J33: =EOMONTH(J32,0)+1 -> 40483 | Q33: =Q32+1 -> 2020
I34: =I33+1 -> 12 | J34: =EOMONTH(J33,0)+1 -> 40513 | Q34: =Q33+1 -> 2021
I35: =I34+1 -> 13 | J35: =EOMONTH(J34,0)+1 -> 40544
I36: =I35+1 -> 14 | J36: =EOMONTH(J35,0)+1 -> 40575
I37: =I36+1 -> 15 | J37: =EOMONTH(J36,0)+1 -> 40603
I38: =I37+1 -> 16 | J38: =EOMONTH(J37,0)+1 -> 40634
I39: =I38+1 -> 17 | J39: =EOMONTH(J38,0)+1 -> 40664
I40: =I39+1 -> 18 | J40: =EOMONTH(J39,0)+1 -> 40695
I41: =I40+1 -> 19 | J41: =EOMONTH(J40,0)+1 -> 40725
I42: =I41+1 -> 20 | J42: =EOMONTH(J41,0)+1 -> 40756
I43: =I42+1 -> 21 | J43: =EOMONTH(J42,0)+1 -> 40787
I44: =I43+1 -> 22 | J44: =EOMONTH(J43,0)+1 -> 40817
I45: =I44+1 -> 23 | J45: =EOMONTH(J44,0)+1 -> 40848
I46: =I45+1 -> 24 | J46: =EOMONTH(J45,0)+1 -> 40878
... I166: =I165+1 -> 144 | J166: =EOMONTH(J165,0)+1 -> 44531

Sheet Dane_Index
B1: CZĘŚĆ II Kwartalne wskaźniki makroekonomiczne
B2: Aktualizacja: | C2: 44588 | F2: Powrót do spisu | BY2: Powrót do spisu
B3: WARUNKI ŻYCIA LUDNOŚCI
B4: Wyszczególnienie A – analogiczny okres roku poprzedniego=100 A1 – od początku roku do końca okresu (analogiczny okres roku poprzedniego=100) B – okres poprzedni=100 | D4: 2000 | H4: 2001 | L4: 2002 | P4: 2003 | T4: 2004 | X4: 2005 | AB4: 2006 | AF4: 2007 | AJ4: 2008 | AN4: 2009 | AR4: 2010 | AV4: 2011 | AZ4: 2012 | BD4: 2013 | BH4: 2014 | BL4: 2015 | BP4: 2016 | BT4: 2017 | BX4: 2018 | CB4: 2019 | CF4: 2020 | CJ4: 2021
D5: 1 kw. | E5: 2 kw. | F5: 3 kw. | G5: 4 kw. | H5: 1 kw. | I5: 2 kw. | J5: 3 kw. | K5: 4 kw. | L5: 1 kw. | M5: 2 kw. | N5: 3 kw. | O5: 4 kw. | P5: 1 kw. | Q5: 2 kw. | R5: 3 kw. | S5: 4 kw. | T5: 1 kw. | U5: 2 kw. | V5: 3 kw. | W5: 4 kw. | X5: 1 kw. | Y5: 2 kw. | Z5: 3 kw. | AA5: 4 kw. | AB5: 1 kw. | AC5: 2 kw. | AD5: 3 kw. | AE5: 4 kw. | AF5: 1 kw. | AG5: 2 kw. | AH5: 3 kw. | AI5: 4 kw. | AJ5: 1 kw. | AK5: 2 kw. | AL5: 3 kw. | AM5: 4 kw. | AN5: 1 kw. | AO5: 2 kw. | AP5: 3 kw. | AQ5: 4 kw. | AR5: 1 kw. | AS5: 2 kw. | AT5: 3 kw. | AU5: 4 kw. | AV5: 1 kw. | AW5: 2 kw. | AX5: 3 kw. | AY5: 4 kw. | AZ5: 1 kw. | BA5: 2 kw. | BB5: 3 kw. | BC5: 4 kw. | BD5: 1 kw. | BE5: 2 kw. | BF5: 3 kw. | BG5: 4 kw. | BH5: 1 kw. | BI5: 2 kw. | BJ5: 3 kw. | BK5: 4 kw. | BL5: 1 kw. | BM5: 2 kw. | BN5: 3 kw. | BO5: 4 kw. | BP5: 1 kw. | BQ5: 2 kw. | BR5: 3 kw. | BS5: 4 kw. | BT5: 1 kw. | BU5: 2 kw. | BV5: 3 kw. | BW5: 4 kw. | BX5: 1 kw. | BY5: 2 kw. | BZ5: 3 kw. | CA5: 4 kw. | CB5: 1 kw. | CC5: 2 kw. | CD5: 3 kw. | CE5: 4 kw. | CF5: 1 kw. | CG5: 2 kw. | CH5: 3 kw. | CI5: 4 kw. | CJ5: 1 kw. | CK5: 2 kw. | CL5: 3 kw. | CM5: 4 kw.
B6: WARUNKI ŻYCIA LUDNOŚCI | D6: 1868.65 | E6: 1869.78 | F6: 1905.76 | G6: 2051.74 | H6: 2043.55 | I6: 2006.92 | J6: 2047.29 | K6: 2152.99 | L6: 2155.54 | M6: 2061.95 | N6: 2095.81 | O6: 2225.41 | P6: 2228.68 | Q6: 2141.01 | R6: 2160.02 | S6: 2276.84 | T6: 2332.17 | U6: 2230.53 | V6: 2269.93 | W6: 2405.46 | X6: 2415.45 | Y6: 2318.53 | Z6: 2347.24 | AA6: 2528.62 | AB6: 2530.18 | AC6: 2427.27 | AD6: 2464.66 | AE6: 2662.51 | AF6: 2709.14 | AG6: 2644.34 | AH6: 2703.41 | AI6: 2899.83 | AJ6: 2983.98 | AK6: 2951.36 | AL6: 2968.55 | AM6: 3096.55 | AN6: 3185.61 | AO6: 3081.48 | AP6: 3113.86 | AQ6: 3243.6 | AR6: 3316.38 | AS6: 3197.85 | AT6: 3203.08 | AU6: 3438.21 | AV6: 3466.33 | AW6: 3366.11 | AX6: 3416 | AY6: 3586.75 | AZ6: 3646.09 | BA6: 3496.82 | BB6: 3510.22 | BC6: 3690.3 | BD6: 3740.05 | BE6: 3612.51 | BF6: 3651.72 | BG6: 3823.32 | BH6: 3895.31 | BI6: 3739.97 | BJ6: 3781.14 | BK6: 3942.67 | BL6: 4054.89 | BM6: 3854.88 | BN6: 3895.33 | BO6: 4066.95 | BP6: 4181.49 | BQ6: 4019.08 | BR6: 4055.04 | BS6: 4218.92 | BT6: 4353.55 | BU6: 4220.69 | BV6: 4255.59 | BW6: 4516.69 | BX6: 4622.84 | BY6: 4521.08 | BZ6: 4580.2 | CA6: 4863.74 | CB6: 4950.94 | CC6: 4839.24 | CD6: 4931.59 | CE6: 5198.58 | CF6: 5331.47 | CG6: 5024.48 | CH6: 5168.93 | CI6: 5457.98 | CJ6: 5681.56 | CK6: 5504.52 | CL6: 5657.3
B7: Przeciętne miesięczne wynagrodzenie nominalne bruttoa w gospodarce narodowej | C7: w zł
C8: A | D8: 115.5 | E8: 112.6 | F8: 111.2 | G8: 110.6 | H8: 109.4 | I8: 107.3 | J8: 107.4 | K8: 104.9 | L8: 105.5 | M8: 102.7 | N8: 102.4 | O8: 103.4 | P8: 103.4 | Q8: 103.8 | R8: 103.1 | S8: 102.3 | T8: 104.6 | U8: 104.2 | V8: 105.1 | W8: 105.6 | X8: 103.6 | Y8: 103.9 | Z8: 103.4 | AA8: 105.1 | AB8: 104.7 | AC8: 104.7 | AD8: 105 | AE8: 105.3 | AF8: 107.1 | AG8: 108.9 | AH8: 109.7 | AI8: 108.9 | AJ8: 110.1 | AK8: 111.6 | AL8: 109.8 | AM8: 106.8 | AN8: 106.8 | AO8: 104.4 | AP8: 104.9 | AQ8: 104.7 | AR8: 104.1 | AS8: 103.8 | AT8: 102.9 | AU8: 106 | AV8: 104.5 | AW8: 105.3 | AX8: 106.6 | AY8: 104.3 | AZ8: 105.2 | BA8: 103.9 | BB8: 102.8 | BC8: 102.9 | BD8: 102.6 | BE8: 103.3 | BF8: 104 | BG8: 103.6 | BH8: 104.2 | BI8: 103.5 | BJ8: 103.5 | BK8: 103.1 | BL8: 104.1 | BM8: 103.1 | BN8: 103 | BO8: 103.2 | BP8: 103.1 | BQ8: 104.3 | BR8: 104.1 | BS8: 103.7 | BT8: 104.1 | BU8: 105 | BV8: 104.9 | BW8: 107.1 | BX8: 106.2 | BY8: 107.1 | BZ8: 107.6 | CA8: 107.7 | CB8: 107.1 | CC8: 107 | CD8: 107.7 | CE8: 106.9 | CF8: 107.7 | CG8: 103.8 | CH8: 104.8 | CI8: 105 | CJ8: 106.6 | CK8: 109.6 | CL8: 109.4
C9: A1 | D9: 115.5 | E9: 114 | F9: 113.1 | G9: 112.9 | H9: 109.4 | I9: 108.4 | J9: 108 | K9: 108.9 | L9: 105.5 | M9: 104.1 | N9: 103.5 | O9: 104.3 | P9: 103.4 | Q9: 103.6 | R9: 103.4 | S9: 104.9 | T9: 104.6 | U9: 104.4 | V9: 104.6 | W9: 104.8 | X9: 103.6 | Y9: 103.8 | Z9: 103.6 | AA9: 104.7 | AB9: 104.7 | AC9: 104.7 | AD9: 104.8 | AE9: 104.9 | AF9: 107.1 | AG9: 108 | AH9: 108.6 | AI9: 108.7 | AJ9: 110.1 | AK9: 110.9 | AL9: 110.4 | AM9: 110.2 | AN9: 106.8 | AO9: 105.6 | AP9: 105.5 | AQ9: 105.5 | AR9: 104.1 | AS9: 103.9 | AT9: 103.5 | AU9: 104 | AV9: 104.5 | AW9: 104.9 | AX9: 105.5 | AY9: 105.4 | AZ9: 105.2 | BA9: 104.6 | BB9: 104 | BC9: 103.5 | BD9: 102.6 | BE9: 102.9 | BF9: 103.3 | BG9: 103.4 | BH9: 104.2 | BI9: 103.9 | BJ9: 103.7 | BK9: 103.4 | BL9: 104.1 | BM9: 103.6 | BN9: 103.4 | BO9: 103.2 | BP9: 103.1 | BQ9: 103.6 | BR9: 103.7 | BS9: 103.6 | BT9: 104.1 | BU9: 104.6 | BV9: 104.9 | BW9: 105.4 | BX9: 106.2 | BY9: 106.7 | BZ9: 106.9 | CA9: 107 | CB9: 107.1 | CC9: 107.1 | CD9: 107.3 | CE9: 107.2 | CF9: 107.7 | CG9: 105.8 | CH9: 105.5 | CI9: 105 | CJ9: 106.6 | CK9: 108 | CL9: 108.5
C10: B | D10: 100.7 | E10: 100.1 | F10: 101.9 | G10: 107.7 | H10: 99.6 | I10: 98.2 | J10: 102 | K10: 105.2 | L10: 100.1 | M10: 95.7 | N10: 101.6 | O10: 106.2 | P10: 100.1 | Q10: 96.1 | R10: 100.9 | S10: 105.4 | T10: 102.4 | U10: 95.6 | V10: 101.8 | W10: 106 | X10: 100.4 | Y10: 96 | Z10: 101.2 | AA10: 107.7 | AB10: 100.1 | AC10: 95.9 | AD10: 101.5 | AE10: 108 | AF10: 101.8 | AG10: 97.6 | AH10: 102.2 | AI10: 107.3 | AJ10: 102.9 | AK10: 98.9 | AL10: 100.6 | AM10: 104.3 | AN10: 102.9 | AO10: 96.7 | AP10: 101.1 | AQ10: 104.2 | AR10: 102.2 | AS10: 96.4 | AT10: 100.2 | AU10: 107.3 | AV10: 100.8 | AW10: 97.1 | AX10: 101.5 | AY10: 105 | AZ10: 101.7 | BA10: 95.9 | BB10: 100.4 | BC10: 105.1 | BD10: 101.3 | BE10: 96.6 | BF10: 101.1 | BG10: 104.7 | BH10: 101.9 | BI10: 96 | BJ10: 101.1 | BK10: 104.3 | BL10: 102.8 | BM10: 95.1 | BN10: 101 | BO10: 104.4 | BP10: 102.8 | BQ10: 96.1 | BR10: 100.9 | BS10: 104 | BT10: 103.2 | BU10: 96.9 | BV10: 100.8 | BW10: 106.1 | BX10: 102.4 | BY10: 97.8 | BZ10: 101.3 | CA10: 106.2 | CB10: 101.8 | CC10: 97.7 | CD10: 101.9 | CE10: 105.4 | CF10: 102.6 | CG10: 94.2 | CH10: 102.9 | CI10: 105.6 | CJ10: 104.1 | CK10: 96.9 | CL10: 102.8
B11: Przeciętne miesięczne wynagrodzenie nominalne brutto w sferze budżetowej | C11: w zł | D11: 2046.43 | E11: 1751.15 | F11: 1813.5 | G11: 2116.43 | H11: 2330.18 | I11: 1932.41 | J11: 1984.64 | K11: 2098.57 | L11: 2492.58 | M11: 1958.86 | N11: 1985.47 | O11: 2149.53 | P11: 2601.11 | Q11: 2098.18 | R11: 2117.08 | S11: 2244.94 | T11: 2736.12 | U11: 2226.77 | V11: 2233.77 | W11: 2342.2 | X11: 2876.89 | Y11: 2304.04 | Z11: 2327.4 | AA11: 2497.59 | AB11: 2986.24 | AC11: 2410.73 | AD11: 2448.6 | AE11: 2640.55 | AF11: 3104.5 | AG11: 2582.76 | AH11: 2582.6 | AI11: 2827 | AJ11: 3334.46 | AK11: 2937.79 | AL11: 2915.76 | AM11: 3219.37 | AN11: 3712.9 | AO11: 3115.23 | AP11: 3110.88 | AQ11: 3304.14 | AR11: 4052 | AS11: 3183.02 | AT11: 3218.1 | AU11: 3566 | AV11: 4260.48 | AW11: 3362.34 | AX11: 3458.77 | AY11: 3715.78 | AZ11: 4485.53 | BA11: 3483.91 | BB11: 3594.17 | BC11: 3841.63 | BD11: 4655.48 | BE11: 3642.41 | BF11: 3744.02 | BG11: 3946.81 | BH11: 4799.57 | BI11: 3750.73 | BJ11: 3807.57 | BK11: 4078.77 | BL11: 4920.47 | BM11: 3840.74 | BN11: 3899.84 | BO11: 4169.68 | BP11: 5004.17 | BQ11: 3982.83 | BR11: 4049.11 | BS11: 4365.79 | BT11: 5162.43 | BU11: 4110.81 | BV11: 4123.05 | BW11: 4613.17 | BX11: 5384.73 | BY11: 4327.32 | BZ11: 4442.46 | CA11: 4850.78 | CB11: 5748.64 | CC11: 4532.04 | CD11: 4858.42 | CE11: 5306.15 | CF11: 6269.83 | CG11: 5007.64 | CH11: 5325.65 | CI11: 5698.13 | CJ11: 6765.85 | CK11: 5292.39 | CL11: 5567.21
C12: A | D12: . | E12: . | F12: . | G12: . | H12: . | I12: . | J12: . | K12: . | L12: . | M12: . | N12: . | O12: . | P12: . | Q12: . | R12: . | S12: . | T12: . | U12: . | V12: . | W12: . | X12: . | Y12: . | Z12: . | AA12: . | AB12: . | AC12: . | AD12: . | AE12: . | AF12: 104 | AG12: 107.1 | AH12: 105.5 | AI12: 107.1 | AJ12: 107.4 | AK12: 113.7 | AL12: 112.9 | AM12: 113.9 | AN12: 111.3 | AO12: 106 | AP12: 106.7 | AQ12: 106.8 | AR12: 109.1 | AS12: 102.1 | AT12: 103.4 | AU12: 107.9 | AV12: 105.1 | AW12: 105.6 | AX12: 107.5 | AY12: 104.2 | AZ12: 105.3 | BA12: 103.6 | BB12: 103.9 | BC12: 103.4 | BD12: 103.8 | BE12: 104.5 | BF12: 104.2 | BG12: 102.7 | BH12: 103.1 | BI12: 103 | BJ12: 101.7 | BK12: 103.3 | BL12: 102.5 | BM12: 102.4 | BN12: 102.4 | BO12: 102.2 | BP12: 101.7 | BQ12: 103.7 | BR12: 103.8 | BS12: 104.7 | BT12: 103.2 | BU12: 103.2 | BV12: 101.8 | BW12: 105.7 | BX12: 104.3 | BY12: 105.3 | BZ12: 107.7 | CA12: 105.2 | CB12: 106.8 | CC12: 104.7 | CD12: 109.4 | CE12: 109.4 | CF12: 109.1 | CG12: 110.5 | CH12: 109.6 | CI12: 107.4 | CJ12: 107.9 | CK12: 105.7 | CL12: 104.5
C13: A1 | D13: . | E13: . | F13: . | G13: . | H13: . | I13: . | J13: . | K13: . | L13: . | M13: . | N13: . | O13: . | P13: . | Q13: . | R13: . | S13: . | T13: . | U13: . | V13: . | W13: . | X13: . | Y13: . | Z13: . | AA13: . | AB13: . | AC13: . | AD13: . | AE13: . | AF13: 104 | AG13: 105.3 | AH13: 105.4 | AI13: 105.8 | AJ13: 107.4 | AK13: 110.4 | AL13: 111.1 | AM13: 111.8 | AN13: 111.3 | AO13: 108.8 | AP13: 108.1 | AQ13: 102.6 | AR13: 109.1 | AS13: 105.9 | AT13: 105.1 | AU13: 105.9 | AV13: 105.1 | AW13: 105.4 | AX13: 106.1 | AY13: 105.6 | AZ13: 105.3 | BA13: 104.5 | BB13: 104.3 | BC13: 104.1 | BD13: 103.8 | BE13: 104.2 | BF13: 104.2 | BG13: 103.8 | BH13: 103.1 | BI13: 103 | BJ13: 102.6 | BK13: 102.8 | BL13: 102.5 | BM13: 102.5 | BN13: 102.5 | BO13: 102.4 | BP13: 101.7 | BQ13: 102.6 | BR13: 103 | BS13: 103.4 | BT13: 103.2 | BU13: 103.2 | BV13: 102.7 | BW13: 103.5 | BX13: 104.3 | BY13: 104.7 | BZ13: 105.7 | CA13: 105.6 | CB13: 106.8 | CC13: 105.9 | CD13: 107 | CE13: 107.6 | CF13: 109.1 | CG13: 109.8 | CH13: 109.7 | CI13: 109.1 | CJ13: 107.9 | CK13: 106.9 | CL13: 106.1
C14: B | D14: . | E14: . | F14: . | G14: . | H14: . | I14: . | J14: . | K14: . | L14: . | M14: . | N14: . | O14: . | P14: . | Q14: . | R14: . | S14: . | T14: . | U14: . | V14: . | W14: . | X14: . | Y14: . | Z14: . | AA14: . | AB14: . | AC14: . | AD14: . | AE14: . | AF14: 117.6 | AG14: 83.2 | AH14: 100 | AI14: 109.5 | AJ14: 118 | AK14: 88.1 | AL14: 99.3 | AM14: 110.4 | AN14: 115.3 | AO14: 83.9 | AP14: 99.9 | AQ14: 106.2 | AR14: 122.6 | AS14: 78.5 | AT14: 101.1 | AU14: 110.8 | AV14: 119.5 | AW14: 78.9 | AX14: 102.9 | AY14: 107.4 | AZ14: 120.7 | BA14: 77.7 | BB14: 103.2 | BC14: 106.9 | BD14: 121.2 | BE14: 78.2 | BF14: 102.8 | BG14: 105.4 | BH14: 121.6 | BI14: 78.1 | BJ14: 101.5 | BK14: 107.1 | BL14: 120.6 | BM14: 78.1 | BN14: 101.5 | BO14: 106.9 | BP14: 120 | BQ14: 79.6 | BR14: 101.7 | BS14: 107.8 | BT14: 118.2 | BU14: 79.6 | BV14: 100.3 | BW14: 111.9 | BX14: 116.7 | BY14: 80.4 | BZ14: 102.7 | CA14: 109.2 | CB14: 118.5 | CC14: 78.8 | CD14: 107.2 | CE14: 109.2 | CF14: 118.2 | CG14: 79.9 | CH14: 106.4 | CI14: 107 | CJ14: 118.7 | CK14: 78.2 | CL14: 105.2
B15: Przeciętne miesięczne wynagrodzenie nominalne brutto w sektorze przedsiębiorstwb | C15: w zł | D15: . | E15: . | F15: . | G15: . | H15: . | I15: . | J15: . | K15: . | L15: . | M15: . | N15: . | O15: . | P15: . | Q15: . | R15: . | S15: . | T15: . | U15: . | V15: . | W15: . | X15: . | Y15: . | Z15: . | AA15: . | AB15: . | AC15: . | AD15: . | AE15: . | AF15: 2737.56 | AG15: 2813.21 | AH15: 2893.07 | AI15: 3106.3 | AJ15: 3057.84 | AK15: 3159.3 | AL15: 3194.23 | AM15: 3329.81 | AN15: 3249.29 | AO15: 3276.94 | AP15: 3317.45 | AQ15: 3456.61 | AR15: 3340.89 | AS15: 3402.05 | AT15: 3385.23 | AU15: 3605.74 | AV15: 3478.91 | AW15: 3573.27 | AX15: 3593.42 | AY15: 3771.08 | AZ15: 3664.16 | BA15: 3681.85 | BB15: 3689.81 | BC15: 3877.5 | BD15: 3740.79 | BE15: 3788.26 | BF15: 3813.25 | BG15: 4005.97 | BH15: 3896.97 | BI15: 3943.91 | BJ15: 3939.22 | BK15: 4139.42 | BL15: 4053.71 | BM15: 4066.34 | BN15: 4081.9 | BO15: 4280.8 | BP15: 4201.91 | BQ15: 4246.21 | BR15: 4254.2 | BS15: 4404.17 | BT15: 4390.54 | BU15: 4477.18 | BV15: 4510.86 | BW15: 4739.91 | BX15: 4700.11 | BY15: 4812.84 | BZ15: 4822.83 | CA15: 5071.41 | CB15: 5015.03 | CC15: 5142.59 | CD15: 5150.15 | CE15: 5368.01 | CF15: 5367.68 | CG15: 5248.83 | CH15: 5371.81 | CI15: 5656.51 | CJ15: 5675.54 | CK15: 5775.25 | CL15: 5885.75 | CM15: 6221.04
C16: A | D16: . | E16: . | F16: . | G16: . | H16: . | I16: . | J16: . | K16: . | L16: . | M16: . | N16: . | O16: . | P16: . | Q16: . | R16: . | S16: . | T16: . | U16: . | V16: . | W16: . | X16: . | Y16: . | Z16: . | AA16: . | AB16: . | AC16: . | AD16: . | AE16: . | AF16: 107.8 | AG16: 109 | AH16: 110.1 | AI16: 110.1 | AJ16: 111.7 | AK16: 112.3 | AL16: 110.4 | AM16: 107.2 | AN16: 106.3 | AO16: 103.7 | AP16: 103.9 | AQ16: 103.8 | AR16: 102.8 | AS16: 103.8 | AT16: 102 | AU16: 104.3 | AV16: 104.1 | AW16: 105 | AX16: 106.1 | AY16: 104.6 | AZ16: 105.3 | BA16: 103 | BB16: 102.7 | BC16: 102.8 | BD16: 102.1 | BE16: 102.9 | BF16: 103.3 | BG16: 103.3 | BH16: 104.2 | BI16: 104.1 | BJ16: 103.3 | BK16: 103.3 | BL16: 104 | BM16: 103.1 | BN16: 103.6 | BO16: 103.4 | BP16: 103.7 | BQ16: 104.4 | BR16: 104.2 | BS16: 102.9 | BT16: 104.5 | BU16: 105.4 | BV16: 106 | BW16: 107.6 | BX16: 107.1 | BY16: 107.5 | BZ16: 106.9 | CA16: 107 | CB16: 106.7 | CC16: 106.9 | CD16: 106.8 | CE16: 105.8 | CF16: 107 | CG16: 102.1 | CH16: 104.3 | CI16: 105.4 | CJ16: 105.7 | CK16: 110 | CL16: 109.6 | CM16: 110
C17: A1 | D17: . | E17: . | F17: . | G17: . | H17: . | I17: . | J17: . | K17: . | L17: . | M17: . | N17: . | O17: . | P17: . | Q17: . | R17: . | S17: . | T17: . | U17: . | V17: . | W17: . | X17: . | Y17: . | Z17: . | AA17: . | AB17: . | AC17: . | AD17: . | AE17: . | AF17: 107.8 | AG17: 108.4 | AH17: 109 | AI17: 109.3 | AJ17: 111.7 | AK17: 112 | AL17: 111.4 | AM17: 110.3 | AN17: 106.3 | AO17: 105 | AP17: 104.6 | AQ17: 104.4 | AR17: 102.8 | AS17: 103.3 | AT17: 102.9 | AU17: 103.3 | AV17: 104.1 | AW17: 104.6 | AX17: 105.1 | AY17: 105 | AZ17: 105.3 | BA17: 104.2 | BB17: 103.7 | BC17: 103.4 | BD17: 102.1 | BE17: 102.5 | BF17: 102.8 | BG17: 102.9 | BH17: 104.2 | BI17: 104.1 | BJ17: 103.9 | BK17: 103.7 | BL17: 104 | BM17: 103.6 | BN17: 103.6 | BO17: 103.5 | BP17: 103.7 | BQ17: 104 | BR17: 104.1 | BS17: 103.8 | BT17: 104.5 | BU17: 105 | BV17: 105.3 | BW17: 105.9 | BX17: 107.1 | BY17: 107.3 | BZ17: 107.2 | CA17: 107.1 | CB17: 106.7 | CC17: 106.8 | CD17: 106.8 | CE17: 106.5 | CF17: 107 | CG17: 104.5 | CH17: 104.5 | CI17: 104.7 | CJ17: 105.7 | CK17: 107.8 | CL17: 108.4 | CM17: 108.8
C18: B | D18: . | E18: . | F18: . | G18: . | H18: . | I18: . | J18: . | K18: . | L18: . | M18: . | N18: . | O18: . | P18: . | Q18: . | R18: . | S18: . | T18: . | U18: . | V18: . | W18: . | X18: . | Y18: . | Z18: . | AA18: . | AB18: . | AC18: . | AD18: . | AE18: . | AF18: 97 | AG18: 102.8 | AH18: 102.8 | AI18: 107.4 | AJ18: 98.4 | AK18: 103.3 | AL18: 101.1 | AM18: 104.2 | AN18: 97.6 | AO18: 100.9 | AP18: 101.2 | AQ18: 104.2 | AR18: 96.7 | AS18: 101.8 | AT18: 99.5 | AU18: 106.5 | AV18: 96.5 | AW18: 102.7 | AX18: 100.6 | AY18: 104.9 | AZ18: 97.2 | BA18: 100.5 | BB18: 100.2 | BC18: 105.1 | BD18: 96.5 | BE18: 101.3 | BF18: 100.7 | BG18: 105.1 | BH18: 97.3 | BI18: 101.2 | BJ18: 99.9 | BK18: 105.1 | BL18: 97.9 | BM18: 100.3 | BN18: 100.4 | BO18: 104.9 | BP18: 98.2 | BQ18: 101.1 | BR18: 100.2 | BS18: 103.5 | BT18: 99.7 | BU18: 102 | BV18: 100.8 | BW18: 105.1 | BX18: 99.2 | BY18: 102.4 | BZ18: 100.2 | CA18: 105.2 | CB18: 98.9 | CC18: 102.5 | CD18: 100.1 | CE18: 104.2 | CF18: 100 | CG18: 97.8 | CH18: 102.3 | CI18: 105.3 | CJ18: 100.3 | CK18: 101.8 | CL18: 101.9 | CM18: 105.7
